Workbook

Sheet Mapeamento ChatGPT
A1: História | B1: Descrição | C1: ID Ref. | D1: Requisito da referência | E1: Tipo Ref. | F1: ID gerado | G1: Sentença gerada | H1: Tipo atribuído | I1: Identificação | J1: Classificação | K1: Observação | L1: Fusão (1 de N)
A2: HU01 | B2: Login único (user) | C2: RN01 | D2: O sistema deve garantir que cada nome de usuário seja único no cadastro. | E2: RN | F2: RN01 | G2: Cada usuário deve possuir um nome de usuário exclusivo para sua autenticação no sistema. | H2: RN | I2: Identificada | J2: Coincide
A3: HU01 | B3: Login único (user) | C3: RF01 | D3: O sistema deve permitir que o usuário se autentique informando nome de usuário e senha. | E3: RF | F3: RF01 | G3: O sistema deve permitir que o usuário se autentique informando seu nome de usuário e sua senha. | H3: RF | I3: Identificada | J3: Coincide
A4: HU01 | B4: Login único (user) | C4: RF02 | D4: Quando as credenciais forem válidas, o sistema deve conceder acesso de acordo com o perfil do usuário. | E4: RF | I4: Não identificada | K4: Não identificado: concessão de acesso conforme o perfil do usuário. O RNF02 gerado trata apenas do bloqueio de usuários não autenticados.
A5: HU01 | B5: Login único (user) | C5: RF03 | D5: Se as credenciais forem inválidas, o sistema deve negar o acesso e exibir mensagem de erro genérica. | E5: RF | F5: RF02 | G5: Se as credenciais informadas forem inválidas, o sistema deve impedir a autenticação do usuário. | H5: RF | I5: Identificada | J5: Coincide | K5: Parcial: não prevê mensagem de erro genérica.
A6: HU01 | B6: Login único (user) | C6: RNF01 | D6: As senhas devem ser armazenadas de forma criptografada (hash com salt), nunca em texto puro. | E6: RNF | F6: RNF01 | G6: O sistema deve garantir a confidencialidade das credenciais de autenticação durante seu armazenamento e utilização. | H6: RNF | I6: Identificada | J6: Coincide | K6: Parcial: não especifica criptografia (hash com salt).
A7: HU01 | B7: Login único (user) | C7: RNF02 | D7: A transmissão das credenciais deve ocorrer por canal seguro (HTTPS/TLS). | E7: RNF | I7: Não identificada | K7: Não identificado: canal seguro de transmissão (HTTPS/TLS).
A8: HU02 | B8: Agendamento de consulta | C8: RN01 | D8: Se o médico já possuir consulta no horário solicitado, o sistema deve impedir o agendamento e sinalizar o conflito. | E8: RN | I8: Não identificada | K8: Não identificado: conflito de horário do médico.
A9: HU02 | B9: Agendamento de consulta | C9: RN02 | D9: Apenas usuários com perfil de recepcionista devem poder agendar consultas. | E9: RN | F9: RN01 | G9: Apenas o recepcionista pode realizar o agendamento de consultas em nome de um paciente com um médico. | H9: RN | I9: Identificada | J9: Coincide | K9: Mesmo tipo de enunciado (permissão de acesso por perfil) que a referência classifica como RST nas Histórias 3, 4, 6, 8, 9 e 10.
A10: HU02 | B10: Agendamento de consulta | C10: RF01 | D10: O sistema deve permitir que a recepcionista agende uma consulta entre um paciente e um médico. | E10: RF | F10: RF03 | G10: O sistema deve registrar o agendamento da consulta para o paciente com o médico selecionado. | H10: RF | I10: Identificada | J10: Coincide
A11: HU02 | B11: Agendamento de consulta | C11: RF02 | D11: O sistema deve registrar a data e o horário da consulta agendada. | E11: RF | I11: Não identificada | K11: Não identificado: registro de data e horário da consulta.
A12: HU02 | B12: Agendamento de consulta | C12: RF03 | D12: O sistema deve vincular a consulta ao paciente e ao médico correspondentes. | E12: RF | F12: RN02 | G12: Um agendamento deve estar associado a um paciente e a um médico. | H12: RN | I12: Identificada | J12: Diverge | K12: Classificado como RN; na referência é RF.
A13: HU03 | B13: Designação de médico | C13: RF01 | D13: O sistema deve permitir que a recepcionista designe um médico a um paciente. | E13: RF | F13: RF02 | G13: O sistema deve permitir que a recepcionista atribua um médico selecionado ao paciente. | H13: RF | I13: Identificada | J13: Coincide
A14: HU03 | B14: Designação de médico | C14: RF02 | D14: O sistema deve registrar o vínculo entre o médico designado e o paciente. | E14: RF | F14: RF03 | G14: O sistema deve registrar a associação entre o paciente e o médico atribuído. | H14: RF | I14: Identificada | J14: Coincide
A15: HU03 | B15: Designação de médico | C15: RF03 | D15: O sistema deve permitir a consulta dos médicos disponíveis para designação. | E15: RF | I15: Não identificada | K15: Não identificado: consulta dos médicos disponíveis.
A16: HU03 | B16: Designação de médico | C16: RST01 | D16: Apenas usuários com perfil de recepcionista devem poder designar médicos. | E16: RST | F16: RN01 | G16: A recepcionista é autorizada a atribuir um médico a um paciente. | H16: RN | I16: Identificada | J16: Diverge | K16: Classificado como RN; na referência é RST. Permissão de acesso por perfil: pela definição de RN adotada no prompt ('quem pode fazer o quê'), a classificação do modelo é compatível com RN.
A17: HU04 | B17: Designação de leito | C17: RN01 | D17: Se o leito já estiver ocupado, o sistema deve impedir sua designação a outro paciente. | E17: RN | F17: RN02 | G17: Um leito deve estar disponível para ser atribuído a um paciente. | H17: RN | I17: Identificada | J17: Coincide
A18: HU04 | B18: Designação de leito | C18: RF01 | D18: O sistema deve permitir que a recepcionista designe um leito a um paciente. | E18: RF | F18: RF01 | G18: O sistema deve permitir que a recepcionista selecione um paciente e lhe atribua um leito disponível. | H18: RF | I18: Identificada | J18: Coincide
A19: HU04 | B19: Designação de leito | C19: RF02 | D19: Quando um leito for designado, o sistema deve marcá-lo como ocupado. | E19: RF | I19: Não identificada | K19: Não identificado: atualização do status do leito para ocupado.
A20: HU04 | B20: Designação de leito | C20: RF03 | D20: O sistema deve permitir a visualização dos leitos disponíveis. | E20: RF | I20: Não identificada | K20: Não identificado: visualização dos leitos disponíveis.
A21: HU04 | B21: Designação de leito | C21: RST01 | D21: Apenas usuários com perfil de recepcionista devem poder designar leitos. | E21: RST | F21: RN01 | G21: A atribuição de um leito ao paciente deve ser realizada pela recepcionista. | H21: RN | I21: Identificada | J21: Diverge | K21: Classificado como RN; na referência é RST. Permissão de acesso por perfil: pela definição de RN adotada no prompt ('quem pode fazer o quê'), a classificação do modelo é compatível com RN.
A22: HU05 | B22: Paciente acessa prontuário | C22: RN01 | D22: O sistema deve restringir o acesso do paciente exclusivamente ao seu próprio prontuário. | E22: RN | F22: RN01 | G22: O paciente pode acessar apenas o seu próprio prontuário médico. | H22: RN | I22: Identificada | J22: Coincide
A23: HU05 | B23: Paciente acessa prontuário | C23: RF01 | D23: O sistema deve permitir que o paciente acesse o seu próprio prontuário. | E23: RF | F23: RF01 | G23: O sistema deve permitir que o paciente acesse seu prontuário médico. | H23: RF | I23: Identificada | J23: Coincide
A24: HU05 | B24: Paciente acessa prontuário | C24: RF02 | D24: O sistema deve exibir os detalhes do prontuário do paciente. | E24: RF | F24: RF02 | G24: O sistema deve apresentar ao paciente os detalhes disponíveis do seu prontuário médico após a solicitação de acesso. | H24: RF | I24: Identificada | J24: Coincide
A25: HU05 | B25: Paciente acessa prontuário | C25: RNF01 | D25: O sistema deve preservar a confidencialidade dos dados do prontuário durante o acesso (canal seguro). | E25: RNF | F25: RNF01 | G25: O acesso ao prontuário médico deve preservar a confidencialidade das informações do paciente. | H25: RNF | I25: Identificada | J25: Coincide
A26: HU05 | B26: Paciente acessa prontuário | C26: RST01 | D26: O acesso ao prontuário deve exigir autenticação do usuário. | E26: RST | I26: Não identificada | K26: Não identificado: exigência de autenticação para o acesso.
A27: HU06 | B27: Médico acessa prontuário | C27: RN01 | D27: O sistema deve permitir o acesso apenas aos prontuários de pacientes designados ao médico. | E27: RN | F27: RN01 | G27: Somente médicos autorizados podem acessar o prontuário médico de um paciente. | H27: RN | I27: Identificada | J27: Coincide | K27: Parcial: não menciona a designação médico-paciente; a restrição aos pacientes designados não é mencionada no texto da História 6 e está explícita apenas na História 7.
A28: HU06 | B28: Médico acessa prontuário | C28: RF01 | D28: O sistema deve permitir que o médico acesse o prontuário de um paciente. | E28: RF | F28: RF01 | G28: O sistema deve permitir que o médico acesse o prontuário médico de um paciente. | H28: RF | I28: Identificada | J28: Coincide
A29: HU06 | B29: Médico acessa prontuário | C29: RF02 | D29: O sistema deve exibir os detalhes do prontuário ao médico. | E29: RF | F29: RF02 | G29: O sistema deve apresentar ao médico os detalhes registrados no prontuário médico do paciente após o acesso autorizado. | H29: RF | I29: Identificada | J29: Coincide
A30: HU06 | B30: Médico acessa prontuário | C30: RST01 | D30: O acesso ao prontuário deve exigir autenticação e ser controlado por perfil de usuário. | E30: RST | F30: RNF01 | G30: O acesso ao prontuário médico deve preservar a confidencialidade das informações do paciente, permitindo sua visualização somente a usuários autorizados. | H30: RNF | I30: Identificada | J30: Diverge | K30: Parcial: cobre o controle por perfil; autenticação não explicitada. Classificado como RNF; na referência é RST.
A31: HU07 | B31: Restrição de acesso a prontuários | C31: RN01 | D31: Um médico pode acessar apenas os prontuários dos pacientes aos quais está designado. | E31: RN | F31: RN01 | G31: O acesso de um médico aos registros médicos de um paciente deve estar condicionado à atribuição desse paciente ao médico. | H31: RN | I31: Identificada | J31: Coincide
A32: HU07 | B32: Restrição de acesso a prontuários | C32: RF01 | D32: Se o médico tentar acessar um prontuário não autorizado, o sistema deve negar o acesso e registrar a tentativa. | E32: RF | F32: RF02 | G32: Se um médico tentar visualizar o registro médico de um paciente que não esteja atribuído a ele, o sistema deve impedir o acesso. | H32: RF | I32: Identificada | J32: Coincide | K32: Parcial: não prevê o registro da tentativa.
A33: HU07 | B33: Restrição de acesso a prontuários | C33: RNF01 | D33: O sistema deve garantir a confidencialidade do paciente por meio de controle de acesso baseado na designação médico-paciente. | E33: RNF | F33: RNF01 | G33: O sistema deve garantir a confidencialidade dos registros médicos, impedindo o acesso não autorizado por médicos. | H33: RNF | I33: Identificada | J33: Coincide
A34: HU08 | B34: Solicitação de exame | C34: RN01 | D34: O médico somente pode solicitar exames para pacientes aos quais está designado. | E34: RN | I34: Não identificada | K34: Não identificado: restrição da solicitação a pacientes designados. A restrição aos pacientes designados não é mencionada no texto da História 8; essa regra está explícita apenas na História 7.
A35: HU08 | B35: Solicitação de exame | C35: RF01 | D35: O sistema deve permitir que o médico solicite um exame médico para um paciente. | E35: RF | F35: RF01 | G35: O sistema deve permitir que o médico solicite um exame médico para um paciente. | H35: RF | I35: Identificada | J35: Coincide
A36: HU08 | B36: Solicitação de exame | C36: RF02 | D36: Quando o médico registra a solicitação, o sistema deve torná-la visível aos especialistas de laboratório. | E36: RF | F36: RF02 | G36: O sistema deve encaminhar a solicitação de exame ao especialista de laboratório responsável pela realização do exame. | H36: RF | I36: Identificada | J36: Coincide
A37: HU08 | B37: Solicitação de exame | C37: RF03 | D37: O sistema deve vincular o exame solicitado ao prontuário do paciente correspondente. | E37: RF | F37: RN02 | G37: O resultado do exame solicitado deve integrar o prontuário médico do paciente. | H37: RN | I37: Identificada | J37: Diverge | K37: Classificado como RN; na referência é RF.
A38: HU08 | B38: Solicitação de exame | C38: RF04 | D38: O sistema deve registrar o médico solicitante e a data/hora da solicitação. | E38: RF | F38: RNF01 | G38: O sistema deve garantir a rastreabilidade das solicitações e resultados de exames registrados no prontuário do paciente. | H38: RNF | I38: Identificada | J38: Diverge | K38: Parcial: rastreabilidade genérica, sem registro explícito de solicitante e data/hora. Classificado como RNF; na referência é RF.
A39: HU08 | B39: Solicitação de exame | C39: RST01 | D39: Somente usuários com perfil médico devem poder solicitar exames. | E39: RST | F39: RN01 | G39: Somente médicos podem solicitar exames médicos para serem realizados pelos especialistas de laboratório. | H39: RN | I39: Identificada | J39: Diverge | K39: Classificado como RN; na referência é RST. Permissão de acesso por perfil: pela definição de RN adotada no prompt ('quem pode fazer o quê'), a classificação do modelo é compatível com RN.
A40: HU09 | B40: Visualização de exames solicitados | C40: RF01 | D40: O sistema deve permitir que o especialista de laboratório visualize os exames solicitados. | E40: RF | F40: RF01 | G40: O sistema deve permitir que o especialista de laboratório visualize os exames médicos solicitados que estejam disponíveis para execução. | H40: RF | I40: Identificada | J40: Coincide
...

Sheet Mapeamento Claude
A1: História | B1: Descrição | C1: ID Ref. | D1: Requisito da referência | E1: Tipo Ref. | F1: ID gerado | G1: Sentença gerada | H1: Tipo atribuído | I1: Identificação | J1: Classificação | K1: Observação | L1: Fusão (1 de N)
A2: HU01 | B2: Login único (user) | C2: RN01 | D2: O sistema deve garantir que cada nome de usuário seja único no cadastro. | E2: RN | F2: RN01 | G2: Cada usuário do sistema deve possuir um login (username) único. | H2: RN | I2: Identificada | J2: Coincide
A3: HU01 | B3: Login único (user) | C3: RF01 | D3: O sistema deve permitir que o usuário se autentique informando nome de usuário e senha. | E3: RF | F3: RF02 | G3: O sistema deve permitir que o usuário se autentique informando username e senha, concedendo acesso somente quando as credenciais forem válidas. | H3: RF | I3: Identificada | J3: Coincide | K3: Requisito único cobre também a concessão de acesso (fusão). | L3: 1 de 2
A4: HU01 | B4: Login único (user) | C4: RF02 | D4: Quando as credenciais forem válidas, o sistema deve conceder acesso de acordo com o perfil do usuário. | E4: RF | F4: RF02 | G4: O sistema deve permitir que o usuário se autentique informando username e senha, concedendo acesso somente quando as credenciais forem válidas. | H4: RF | I4: Identificada | J4: Coincide | K4: Fusão: mesmo requisito cobre RF01 e RF02 da referência. | L4: 1 de 2
A5: HU01 | B5: Login único (user) | C5: RF03 | D5: Se as credenciais forem inválidas, o sistema deve negar o acesso e exibir mensagem de erro genérica. | E5: RF | I5: Não identificada | K5: Não identificado: negativa explícita com mensagem de erro genérica.
A6: HU01 | B6: Login único (user) | C6: RNF01 | D6: As senhas devem ser armazenadas de forma criptografada (hash com salt), nunca em texto puro. | E6: RNF | F6: RNF01 | G6: O sistema deve armazenar as senhas dos usuários de forma criptografada. | H6: RNF | I6: Identificada | J6: Coincide
A7: HU01 | B7: Login único (user) | C7: RNF02 | D7: A transmissão das credenciais deve ocorrer por canal seguro (HTTPS/TLS). | E7: RNF | F7: RNF02 | G7: O sistema deve proteger a confidencialidade das credenciais durante a transmissão. | H7: RNF | I7: Identificada | J7: Coincide
A8: HU02 | B8: Agendamento de consulta | C8: RN01 | D8: Se o médico já possuir consulta no horário solicitado, o sistema deve impedir o agendamento e sinalizar o conflito. | E8: RN | F8: RN02 | G8: Um médico não pode possuir duas consultas agendadas no mesmo horário. | H8: RN | I8: Identificada | J8: Coincide
A9: HU02 | B9: Agendamento de consulta | C9: RN02 | D9: Apenas usuários com perfil de recepcionista devem poder agendar consultas. | E9: RN | F9: RN01 | G9: Somente usuários com o papel de recepcionista podem realizar o agendamento de consultas para pacientes. | H9: RN | I9: Identificada | J9: Coincide | K9: Mesmo tipo de enunciado (permissão de acesso por perfil) que a referência classifica como RST nas Histórias 3, 4, 6, 8, 9 e 10.
A10: HU02 | B10: Agendamento de consulta | C10: RF01 | D10: O sistema deve permitir que a recepcionista agende uma consulta entre um paciente e um médico. | E10: RF | F10: RF03 | G10: Quando a recepcionista confirmar o paciente, o médico, a data e o horário, o sistema deve registrar a consulta agendada. | H10: RF | I10: Identificada | J10: Coincide | K10: Fusão: cobre RF01, RF02 e RF03 da referência. | L10: 1 de 3
A11: HU02 | B11: Agendamento de consulta | C11: RF02 | D11: O sistema deve registrar a data e o horário da consulta agendada. | E11: RF | F11: RF03 | G11: Quando a recepcionista confirmar o paciente, o médico, a data e o horário, o sistema deve registrar a consulta agendada. | H11: RF | I11: Identificada | J11: Coincide | K11: Fusão: registro de data e horário contemplado. | L11: 1 de 3
A12: HU02 | B12: Agendamento de consulta | C12: RF03 | D12: O sistema deve vincular a consulta ao paciente e ao médico correspondentes. | E12: RF | F12: RF03 | G12: Quando a recepcionista confirmar o paciente, o médico, a data e o horário, o sistema deve registrar a consulta agendada. | H12: RF | I12: Identificada | J12: Coincide | K12: Fusão: vínculo com paciente e médico contemplado. | L12: 1 de 3
A13: HU03 | B13: Designação de médico | C13: RF01 | D13: O sistema deve permitir que a recepcionista designe um médico a um paciente. | E13: RF | F13: RF03 | G13: Quando a recepcionista confirmar a seleção, o sistema deve registrar o médico atribuído ao paciente. | H13: RF | I13: Identificada | J13: Coincide | K13: Fusão: cobre RF01 e RF02 da referência. | L13: 1 de 2
A14: HU03 | B14: Designação de médico | C14: RF02 | D14: O sistema deve registrar o vínculo entre o médico designado e o paciente. | E14: RF | F14: RF03 | G14: Quando a recepcionista confirmar a seleção, o sistema deve registrar o médico atribuído ao paciente. | H14: RF | I14: Identificada | J14: Coincide | K14: Fusão: registro do vínculo contemplado. | L14: 1 de 2
A15: HU03 | B15: Designação de médico | C15: RF03 | D15: O sistema deve permitir a consulta dos médicos disponíveis para designação. | E15: RF | F15: RF02 | G15: O sistema deve permitir que a recepcionista selecione um médico dentre os médicos cadastrados para atribuição ao paciente. | H15: RF | I15: Identificada | J15: Coincide
A16: HU03 | B16: Designação de médico | C16: RST01 | D16: Apenas usuários com perfil de recepcionista devem poder designar médicos. | E16: RST | F16: RN02 | G16: Apenas usuários com perfil de recepcionista têm permissão para atribuir um médico a um paciente em nome deste. | H16: RN | I16: Identificada | J16: Diverge | K16: Classificado como RN; na referência é RST. Permissão de acesso por perfil: pela definição de RN adotada no prompt ('quem pode fazer o quê'), a classificação do modelo é compatível com RN.
A17: HU04 | B17: Designação de leito | C17: RN01 | D17: Se o leito já estiver ocupado, o sistema deve impedir sua designação a outro paciente. | E17: RN | F17: RN02 | G17: Um leito somente pode ser atribuído a um paciente se estiver disponível (não ocupado por outro paciente). | H17: RN | I17: Identificada | J17: Coincide
A18: HU04 | B18: Designação de leito | C18: RF01 | D18: O sistema deve permitir que a recepcionista designe um leito a um paciente. | E18: RF | F18: RF01 | G18: O sistema deve permitir que a recepcionista atribua um leito disponível a um paciente. | H18: RF | I18: Identificada | J18: Coincide
A19: HU04 | B19: Designação de leito | C19: RF02 | D19: Quando um leito for designado, o sistema deve marcá-lo como ocupado. | E19: RF | F19: RF03 | G19: Quando um leito for atribuído a um paciente, o sistema deve atualizar o status do leito para ocupado. | H19: RF | I19: Identificada | J19: Coincide
A20: HU04 | B20: Designação de leito | C20: RF03 | D20: O sistema deve permitir a visualização dos leitos disponíveis. | E20: RF | F20: RF02 | G20: O sistema deve exibir a lista de leitos disponíveis para seleção no momento da atribuição. | H20: RF | I20: Identificada | J20: Coincide
A21: HU04 | B21: Designação de leito | C21: RST01 | D21: Apenas usuários com perfil de recepcionista devem poder designar leitos. | E21: RST | F21: RN01 | G21: Apenas usuários com o papel de recepcionista estão autorizados a atribuir um leito a um paciente. | H21: RN | I21: Identificada | J21: Diverge | K21: Classificado como RN; na referência é RST. Permissão de acesso por perfil: pela definição de RN adotada no prompt ('quem pode fazer o quê'), a classificação do modelo é compatível com RN.
A22: HU05 | B22: Paciente acessa prontuário | C22: RN01 | D22: O sistema deve restringir o acesso do paciente exclusivamente ao seu próprio prontuário. | E22: RN | F22: RN01 | G22: O paciente somente pode acessar o prontuário médico do qual é o titular. | H22: RN | I22: Identificada | J22: Coincide
A23: HU05 | B23: Paciente acessa prontuário | C23: RF01 | D23: O sistema deve permitir que o paciente acesse o seu próprio prontuário. | E23: RF | F23: RF01 | G23: O sistema deve permitir que o paciente autenticado visualize os detalhes do seu prontuário médico. | H23: RF | I23: Identificada | J23: Coincide | K23: Fusão: cobre RF01 e RF02 da referência. | L23: 1 de 3
A24: HU05 | B24: Paciente acessa prontuário | C24: RF02 | D24: O sistema deve exibir os detalhes do prontuário do paciente. | E24: RF | F24: RF01 | G24: O sistema deve permitir que o paciente autenticado visualize os detalhes do seu prontuário médico. | H24: RF | I24: Identificada | J24: Coincide | K24: Fusão: exibição dos detalhes contemplada. | L24: 1 de 3
A25: HU05 | B25: Paciente acessa prontuário | C25: RNF01 | D25: O sistema deve preservar a confidencialidade dos dados do prontuário durante o acesso (canal seguro). | E25: RNF | F25: RNF02 | G25: O sistema deve garantir a confidencialidade dos dados do prontuário médico durante a transmissão e o armazenamento. | H25: RNF | I25: Identificada | J25: Coincide
A26: HU05 | B26: Paciente acessa prontuário | C26: RST01 | D26: O acesso ao prontuário deve exigir autenticação do usuário. | E26: RST | F26: RF01 | G26: O sistema deve permitir que o paciente autenticado visualize os detalhes do seu prontuário médico. | H26: RF | I26: Identificada | J26: Diverge | K26: Autenticação aparece como condição embutida no RF01, não como requisito próprio. Classificado como RF; na referência é RST. | L26: 1 de 3
A27: HU06 | B27: Médico acessa prontuário | C27: RN01 | D27: O sistema deve permitir o acesso apenas aos prontuários de pacientes designados ao médico. | E27: RN | F27: RN01 | G27: Apenas usuários com o perfil de médico têm permissão para acessar o prontuário médico do paciente. | H27: RN | I27: Identificada | J27: Coincide | K27: Parcial: não menciona a designação médico-paciente; a restrição aos pacientes designados não é mencionada no texto da História 6 e está explícita apenas na História 7. | L27: 1 de 2
A28: HU06 | B28: Médico acessa prontuário | C28: RF01 | D28: O sistema deve permitir que o médico acesse o prontuário de um paciente. | E28: RF | F28: RF01 | G28: O sistema deve permitir que o médico acesse o prontuário médico do paciente. | H28: RF | I28: Identificada | J28: Coincide
A29: HU06 | B29: Médico acessa prontuário | C29: RF02 | D29: O sistema deve exibir os detalhes do prontuário ao médico. | E29: RF | F29: RF02 | G29: Quando o médico acessar o prontuário médico, o sistema deve exibir os detalhes do prontuário. | H29: RF | I29: Identificada | J29: Coincide
A30: HU06 | B30: Médico acessa prontuário | C30: RST01 | D30: O acesso ao prontuário deve exigir autenticação e ser controlado por perfil de usuário. | E30: RST | F30: RN01 | G30: Apenas usuários com o perfil de médico têm permissão para acessar o prontuário médico do paciente. | H30: RN | I30: Identificada | J30: Diverge | K30: Parcial: cobre o controle por perfil; autenticação não explicitada. Classificado como RN; na referência é RST. Permissão de acesso por perfil: pela definição de RN adotada no prompt ('quem pode fazer o quê'), a classificação do modelo é compatível com RN. | L30: 1 de 2
A31: HU07 | B31: Restrição de acesso a prontuários | C31: RN01 | D31: Um médico pode acessar apenas os prontuários dos pacientes aos quais está designado. | E31: RN | F31: RN01 | G31: O acesso ao prontuário médico de um paciente é restrito aos médicos formalmente designados/atribuídos a esse paciente. | H31: RN | I31: Identificada | J31: Coincide
A32: HU07 | B32: Restrição de acesso a prontuários | C32: RF01 | D32: Se o médico tentar acessar um prontuário não autorizado, o sistema deve negar o acesso e registrar a tentativa. | E32: RF | F32: RF02 | G32: Se o médico não estiver atribuído ao paciente, o sistema deve negar o acesso ao prontuário médico. | H32: RF | I32: Identificada | J32: Coincide | K32: Registro da tentativa contemplado pelo RNF02 gerado (log de auditoria).
A33: HU07 | B33: Restrição de acesso a prontuários | C33: RNF01 | D33: O sistema deve garantir a confidencialidade do paciente por meio de controle de acesso baseado na designação médico-paciente. | E33: RNF | F33: RNF01 | G33: O sistema deve garantir a confidencialidade dos dados médicos dos pacientes por meio de controle de acesso baseado na atribuição médico-paciente. | H33: RNF | I33: Identificada | J33: Coincide
A34: HU08 | B34: Solicitação de exame | C34: RN01 | D34: O médico somente pode solicitar exames para pacientes aos quais está designado. | E34: RN | I34: Não identificada | K34: Não identificado: restrição da solicitação a pacientes designados. A restrição aos pacientes designados não é mencionada no texto da História 8; essa regra está explícita apenas na História 7.
A35: HU08 | B35: Solicitação de exame | C35: RF01 | D35: O sistema deve permitir que o médico solicite um exame médico para um paciente. | E35: RF | F35: RF01 | G35: O sistema deve permitir que o médico solicite um exame laboratorial para um paciente. | H35: RF | I35: Identificada | J35: Coincide
A36: HU08 | B36: Solicitação de exame | C36: RF02 | D36: Quando o médico registra a solicitação, o sistema deve torná-la visível aos especialistas de laboratório. | E36: RF | F36: RF03 | G36: O sistema deve disponibilizar a solicitação de exame registrada aos especialistas de laboratório para execução. | H36: RF | I36: Identificada | J36: Coincide
A37: HU08 | B37: Solicitação de exame | C37: RF03 | D37: O sistema deve vincular o exame solicitado ao prontuário do paciente correspondente. | E37: RF | F37: RF02 | G37: Quando uma solicitação de exame for registrada, o sistema deve associá-la ao prontuário médico do paciente correspondente. | H37: RF | I37: Identificada | J37: Coincide
A38: HU08 | B38: Solicitação de exame | C38: RF04 | D38: O sistema deve registrar o médico solicitante e a data/hora da solicitação. | E38: RF | F38: RNF02 | G38: O sistema deve manter registro de auditoria de cada solicitação de exame realizada. | H38: RNF | I38: Identificada | J38: Diverge | K38: Parcial: auditoria genérica, sem menção explícita a solicitante e data/hora. Classificado como RNF; na referência é RF.
A39: HU08 | B39: Solicitação de exame | C39: RST01 | D39: Somente usuários com perfil médico devem poder solicitar exames. | E39: RST | F39: RN01 | G39: Apenas usuários com perfil de médico podem solicitar exames laboratoriais para pacientes. | H39: RN | I39: Identificada | J39: Diverge | K39: Classificado como RN; na referência é RST. Permissão de acesso por perfil: pela definição de RN adotada no prompt ('quem pode fazer o quê'), a classificação do modelo é compatível com RN.
A40: HU09 | B40: Visualização de exames solicitados | C40: RF01 | D40: O sistema deve permitir que o especialista de laboratório visualize os exames solicitados. | E40: RF | F40: RF01 | G40: O sistema deve permitir que o especialista de laboratório visualize a lista de exames médicos solicitados. | H40: RF | I40: Identificada | J40: Coincide
...

Sheet Requisitos Extras
A1: REQUISITOS GERADOS SEM CORRESPONDÊNCIA NA REFERÊNCIA
A2: História | B2: Modelo | C2: ID gerado | D2: Sentença gerada | E2: Tipo atribuído | F2: Correspondência referência | G2: Observação
A3: HU01 | B3: ChatGPT | C3: RNF02 | D3: O sistema deve impedir o acesso às funcionalidades protegidas por usuários que não estejam autenticados. | E3: RNF | F3: Adicional sustentado | G3: Decorre do objetivo de segurança declarado na história.
A4: HU01 | B4: ChatGPT | C4: RST01 | D4: O mecanismo de autenticação deve utilizar exclusivamente nome de usuário e senha como credenciais de acesso previstas para o requisito de login. | E4: RST | F4: Adicional sustentado | G4: Restrição derivada da forma de autenticação indicada na história.
A5: HU01 | B5: Claude | C5: RF01 | D5: O sistema deve permitir o cadastro de um usuário com username e senha, validando que o username seja único. | E5: RF | F5: Não | G5: Amplia o escopo: a história trata da autenticação, não do cadastro de usuários.
A6: HU01 | B6: Claude | C6: RST01 | D6: O sistema deve utilizar autenticação baseada em username e senha. | E6: RST | F6: Adicional sustentado | G6: Restrição derivada da forma de autenticação indicada na história.
A7: HU02 | B7: ChatGPT | C7: RF01 | D7: O sistema deve permitir que o recepcionista selecione um paciente para o qual deseja realizar o agendamento. | E7: RF | F7: Adicional sustentado | G7: Decomposição do agendamento em etapas de seleção.
A8: HU02 | B8: ChatGPT | C8: RF02 | D8: O sistema deve permitir que o recepcionista selecione um médico para o atendimento do paciente. | E8: RF | F8: Adicional sustentado | G8: Decomposição do agendamento em etapas de seleção.
A9: HU02 | B9: Claude | C9: RF01 | D9: O sistema deve permitir que a recepcionista selecione um paciente cadastrado para o agendamento da consulta. | E9: RF | F9: Adicional sustentado | G9: Decomposição do agendamento em etapas de seleção.
A10: HU02 | B10: Claude | C10: RF02 | D10: O sistema deve permitir que a recepcionista selecione um médico disponível para o agendamento da consulta. | E10: RF | F10: Adicional sustentado | G10: Decomposição do agendamento em etapas de seleção.
A11: HU02 | B11: Claude | C11: RNF01 | D11: O sistema deve registrar, para fins de auditoria, o usuário responsável pela criação de cada agendamento de consulta. | E11: RNF | F11: Adicional sustentado | G11: Sustentado como padrão do domínio hospitalar, conforme instrução do prompt quanto aos requisitos implícitos.
A12: HU03 | B12: ChatGPT | C12: RN02 | D12: Um paciente que não conhece um médico pode receber um médico atribuído pela recepcionista. | E12: RN | F12: Adicional sustentado | G12: Reproduz a justificativa declarada na história.
A13: HU03 | B13: ChatGPT | C13: RF01 | D13: O sistema deve permitir que a recepcionista selecione um paciente para realizar a atribuição de um médico. | E13: RF | F13: Adicional sustentado | G13: Decomposição da atribuição em etapas.
... A36: HU10 | B36: Claude | C36: RST01 | D36: O sistema deve estar em conformidade com a legislação de proteção de dados de saúde aplicável ao registro e à alteração de prontuários médicos. | E36: RST | F36: Adicional sustentado | G36: Sustentado como padrão do domínio hospitalar, conforme instrução do prompt quanto aos requisitos implícitos.

Sheet Avaliação
A1: História | B1: LLM | C1: ID | D1: Tipo | E1: Elemento gerado | F1: Correspondência referência | G1: Corretude | H1: Completude | I1: Não ambiguidade | J1: Verificabilidade | K1: Observação/Justificativa
A2: HU01 | B2: ChatGPT | C2: RF01 | D2: RF | E2: O sistema deve permitir que o usuário se autentique informando seu nome de usuário e sua senha. | F2: Sim | G2: A | H2: A | I2: A | J2: A
A3: HU01 | B3: ChatGPT | C3: RF02 | D3: RF | E3: Se as credenciais informadas forem inválidas, o sistema deve impedir a autenticação do usuário. | F3: Parcial | G3: A | H3: AP | I3: A | J3: A | K3: Parcial: não prevê mensagem de erro genérica. | Completude AP: não indica o retorno ao usuário diante da falha de autenticação.
A4: HU01 | B4: ChatGPT | C4: RN01 | D4: RN | E4: Cada usuário deve possuir um nome de usuário exclusivo para sua autenticação no sistema. | F4: Sim | G4: A | H4: A | I4: A | J4: A
A5: HU01 | B5: ChatGPT | C5: RNF01 | D5: RNF | E5: O sistema deve garantir a confidencialidade das credenciais de autenticação durante seu armazenamento e utilização. | F5: Parcial | G5: A | H5: AP | I5: AP | J5: AP | K5: Parcial: não especifica criptografia (hash com salt). | Completude AP: não indica o mecanismo de proteção. Não ambiguidade AP: 'utilização' admite leituras distintas. Verificabilidade AP: exige critério objetivo de confidencialidade.
A6: HU01 | B6: ChatGPT | C6: RNF02 | D6: RNF | E6: O sistema deve impedir o acesso às funcionalidades protegidas por usuários que não estejam autenticados. | F6: Adicional sustentado | G6: A | H6: AP | I6: AP | J6: AP | K6: Sustentado pela história. Decorre do objetivo de segurança declarado na história. | Completude AP: não identifica quais funcionalidades devem ser protegidas. Não ambiguidade AP: 'funcionalidades protegidas' admite interpretações diferentes. Verificabilidade AP: sem a delimitação dessas funcionalidades, a verificação objetiva completa depende de informações adicionais.
A7: HU01 | B7: ChatGPT | C7: RST01 | D7: RST | E7: O mecanismo de autenticação deve utilizar exclusivamente nome de usuário e senha como credenciais de acesso previstas para o requisito de login. | F7: Adicional sustentado | G7: A | H7: A | I7: AP | J7: A | K7: Sustentado pela história. Restrição derivada da forma de autenticação indicada na história. | Não ambiguidade AP: a expressão 'previstas para o requisito de login' torna a redação confusa.
A8: HU02 | B8: ChatGPT | C8: RF01 | D8: RF | E8: O sistema deve permitir que o recepcionista selecione um paciente para o qual deseja realizar o agendamento. | F8: Adicional sustentado | G8: A | H8: A | I8: A | J8: A | K8: Sustentado pela história. Decomposição do agendamento em etapas de seleção.
A9: HU02 | B9: ChatGPT | C9: RF02 | D9: RF | E9: O sistema deve permitir que o recepcionista selecione um médico para o atendimento do paciente. | F9: Adicional sustentado | G9: A | H9: A | I9: A | J9: A | K9: Sustentado pela história. Decomposição do agendamento em etapas de seleção.
A10: HU02 | B10: ChatGPT | C10: RF03 | D10: RF | E10: O sistema deve registrar o agendamento da consulta para o paciente com o médico selecionado. | F10: Sim | G10: A | H10: AP | I10: A | J10: A | K10: Completude AP: não contempla data e horário, informações relevantes para o agendamento.
A11: HU02 | B11: ChatGPT | C11: RN01 | D11: RN | E11: Apenas o recepcionista pode realizar o agendamento de consultas em nome de um paciente com um médico. | F11: Sim | G11: A | H11: A | I11: A | J11: A
A12: HU02 | B12: ChatGPT | C12: RN02 | D12: RN | E12: Um agendamento deve estar associado a um paciente e a um médico. | F12: Sim | G12: A | H12: A | I12: A | J12: A | K12: Classificado como RN; na referência é RF.
A13: HU03 | B13: ChatGPT | C13: RF01 | D13: RF | E13: O sistema deve permitir que a recepcionista selecione um paciente para realizar a atribuição de um médico. | F13: Adicional sustentado | G13: A | H13: A | I13: A | J13: A | K13: Sustentado pela história. Decomposição da atribuição em etapas.
A14: HU03 | B14: ChatGPT | C14: RF02 | D14: RF | E14: O sistema deve permitir que a recepcionista atribua um médico selecionado ao paciente. | F14: Sim | G14: A | H14: A | I14: A | J14: A
A15: HU03 | B15: ChatGPT | C15: RF03 | D15: RF | E15: O sistema deve registrar a associação entre o paciente e o médico atribuído. | F15: Sim | G15: A | H15: A | I15: A | J15: A
A16: HU03 | B16: ChatGPT | C16: RN01 | D16: RN | E16: A recepcionista é autorizada a atribuir um médico a um paciente. | F16: Sim | G16: A | H16: A | I16: A | J16: A | K16: Classificado como RN; na referência é RST.
A17: HU03 | B17: ChatGPT | C17: RN02 | D17: RN | E17: Um paciente que não conhece um médico pode receber um médico atribuído pela recepcionista. | F17: Adicional sustentado | G17: A | H17: A | I17: AP | J17: AP | K17: Sustentado pela história. Reproduz a justificativa declarada na história. | Não ambiguidade AP: 'não conhece um médico' é uma condição subjetiva, que admite interpretações diferentes. Verificabilidade AP: a constatação dessa condição depende de informações adicionais, pois ela não tem critério objetivo.
A18: HU04 | B18: ChatGPT | C18: RF01 | D18: RF | E18: O sistema deve permitir que a recepcionista selecione um paciente e lhe atribua um leito disponível. | F18: Sim | G18: A | H18: A | I18: A | J18: A
A19: HU04 | B19: ChatGPT | C19: RF02 | D19: RF | E19: Quando um leito for atribuído a um paciente, o sistema deve registrar a associação entre o paciente e o leito. | F19: Adicional sustentado | G19: A | H19: A | I19: A | J19: A | K19: Sustentado pela história. Registro do vínculo paciente-leito decorre da atribuição.
A20: HU04 | B20: ChatGPT | C20: RN01 | D20: RN | E20: A atribuição de um leito ao paciente deve ser realizada pela recepcionista. | F20: Sim | G20: A | H20: A | I20: A | J20: A | K20: Classificado como RN; na referência é RST.
A21: HU04 | B21: ChatGPT | C21: RN02 | D21: RN | E21: Um leito deve estar disponível para ser atribuído a um paciente. | F21: Sim | G21: A | H21: A | I21: A | J21: A
A22: HU05 | B22: ChatGPT | C22: RF01 | D22: RF | E22: O sistema deve permitir que o paciente acesse seu prontuário médico. | F22: Sim | G22: A | H22: A | I22: A | J22: A
A23: HU05 | B23: ChatGPT | C23: RF02 | D23: RF | E23: O sistema deve apresentar ao paciente os detalhes disponíveis do seu prontuário médico após a solicitação de acesso. | F23: Sim | G23: A | H23: A | I23: AP | J23: AP | K23: Não ambiguidade AP: 'detalhes disponíveis' não delimita o conteúdo exibido. Verificabilidade AP: depende dessa delimitação.
A24: HU05 | B24: ChatGPT | C24: RN01 | D24: RN | E24: O paciente pode acessar apenas o seu próprio prontuário médico. | F24: Sim | G24: A | H24: A | I24: A | J24: A
A25: HU05 | B25: ChatGPT | C25: RNF01 | D25: RNF | E25: O acesso ao prontuário médico deve preservar a confidencialidade das informações do paciente. | F25: Sim | G25: A | H25: AP | I25: A | J25: AP | K25: Completude AP: não indica como a confidencialidade é preservada. Verificabilidade AP: ausência de critério objetivo.
A26: HU06 | B26: ChatGPT | C26: RF01 | D26: RF | E26: O sistema deve permitir que o médico acesse o prontuário médico de um paciente. | F26: Sim | G26: A | H26: A | I26: A | J26: A
A27: HU06 | B27: ChatGPT | C27: RF02 | D27: RF | E27: O sistema deve apresentar ao médico os detalhes registrados no prontuário médico do paciente após o acesso autorizado. | F27: Sim | G27: A | H27: A | I27: AP | J27: A | K27: Não ambiguidade AP: 'os detalhes registrados' não delimita o conteúdo exibido.
A28: HU06 | B28: ChatGPT | C28: RN01 | D28: RN | E28: Somente médicos autorizados podem acessar o prontuário médico de um paciente. | F28: Parcial | G28: A | H28: AP | I28: AP | J28: AP | K28: Parcial: não menciona a designação médico-paciente; a restrição aos pacientes designados não é mencionada no texto da História 6 e está explícita apenas na História 7. | Completude AP: não indica o critério que torna um médico autorizado. Não ambiguidade AP: 'médicos autorizados' admite interpretações diferentes. Verificabilidade AP: sem o critério de autorização, a verificação objetiva completa depende de informações adicionais.
A29: HU06 | B29: ChatGPT | C29: RNF01 | D29: RNF | E29: O acesso ao prontuário médico deve preservar a confidencialidade das informações do paciente, permitindo sua visualização somente a usuários autorizados. | F29: Parcial | G29: A | H29: AP | I29: AP | J29: AP | K29: Parcial: cobre o controle por perfil; autenticação não explicitada. Classificado como RNF; na referência é RST. | Completude AP: não indica como a confidencialidade é preservada. Não ambiguidade AP: 'usuários autorizados' admite interpretações diferentes. Verificabilidade AP: a confidencialidade é enunciada sem critério de aceitação, e a verificação objetiva completa depende de informações adicionais.
A30: HU07 | B30: ChatGPT | C30: RF01 | D30: RF | E30: O sistema deve permitir que um médico visualize os registros médicos somente dos pacientes que estejam atribuídos a ele. | F30: Adicional sustentado | G30: A | H30: A | I30: A | J30: A | K30: Sustentado pela história. Formulação positiva da mesma restrição de acesso.
A31: HU07 | B31: ChatGPT | C31: RF02 | D31: RF | E31: Se um médico tentar visualizar o registro médico de um paciente que não esteja atribuído a ele, o sistema deve impedir o acesso. | F31: Parcial | G31: A | H31: A | I31: A | J31: A | K31: Parcial: não prevê o registro da tentativa.
A32: HU07 | B32: ChatGPT | C32: RN01 | D32: RN | E32: O acesso de um médico aos registros médicos de um paciente deve estar condicionado à atribuição desse paciente ao médico. | F32: Sim | G32: A | H32: A | I32: A | J32: A
A33: HU07 | B33: ChatGPT | C33: RNF01 | D33: RNF | E33: O sistema deve garantir a confidencialidade dos registros médicos, impedindo o acesso não autorizado por médicos. | F33: Sim | G33: A | H33: A | I33: AP | J33: AP | K33: Não ambiguidade AP: 'acesso não autorizado' não explicita o critério de autorização e admite interpretações diferentes. Verificabilidade AP: a confidencialidade é enunciada de forma genérica, e a verificação objetiva completa depende de um critério de aceitação não informado.
A34: HU08 | B34: ChatGPT | C34: RF01 | D34: RF | E34: O sistema deve permitir que o médico solicite um exame médico para um paciente. | F34: Sim | G34: A | H34: A | I34: A | J34: A
A35: HU08 | B35: ChatGPT | C35: RF02 | D35: RF | E35: O sistema deve encaminhar a solicitação de exame ao especialista de laboratório responsável pela realização do exame. | F35: Sim | G35: A | H35: AP | I35: AP | J35: AP | K35: Completude AP: não indica como é determinado o especialista que recebe a solicitação. Não ambiguidade AP: 'especialista de laboratório responsável' admite interpretações diferentes. Verificabilidade AP: sem a definição do destinatário, a verificação objetiva completa do encaminhamento depende de informações adicionais.
A36: HU08 | B36: ChatGPT | C36: RFO3 | D36: RF | E36: O sistema deve registrar o resultado do exame no prontuário médico do paciente após sua realização pelo especialista de laboratório. | F36: Não | G36: AP | H36: A | I36: A | J36: A | K36: Sem sustentação na história. A história trata da solicitação do exame, não do registro de resultados. ID gerado com erro de digitação (RFO3 em vez de RF03). | Corretude AP: acrescenta o registro do resultado, que extrapola o conteúdo declarado na história.
A37: HU08 | B37: ChatGPT | C37: RN01 | D37: RN | E37: Somente médicos podem solicitar exames médicos para serem realizados pelos especialistas de laboratório. | F37: Sim | G37: A | H37: A | I37: A | J37: A | K37: Classificado como RN; na referência é RST.
A38: HU08 | B38: ChatGPT | C38: RN02 | D38: RN | E38: O resultado do exame solicitado deve integrar o prontuário médico do paciente. | F38: Sim | G38: A | H38: A | I38: A | J38: A | K38: Classificado como RN; na referência é RF.
A39: HU08 | B39: ChatGPT | C39: RNF01 | D39: RNF | E39: O sistema deve garantir a rastreabilidade das solicitações e resultados de exames registrados no prontuário do paciente. | F39: Parcial | G39: A | H39: AP | I39: AP | J39: AP | K39: Parcial: rastreabilidade genérica, sem registro explícito de solicitante e data/hora. Classificado como RNF; na referência é RF. | Completude AP: não especifica quais informações devem ser registradas. Não ambiguidade AP: 'rastreabilidade' admite interpretações diferentes quanto ao que deve ser rastreado. Verificabilidade AP: sem essas informações, a verificação objetiva completa depende de informações adicionais.
A40: HU09 | B40: ChatGPT | C40: RF01 | D40: RF | E40: O sistema deve permitir que o especialista de laboratório visualize os exames médicos solicitados que estejam disponíveis para execução. | F40: Sim | G40: A | H40: A | I40: AP | J40: A | K40: Não ambiguidade AP: 'disponíveis para execução' não equivale claramente a exames pendentes.
...

Sheet Resultados
A1: RESULTADOS
A3: 1. Cobertura de Requisitos (CR) por categoria
A4: Categoria | B4: Total ref. | C4: ChatGPT | D4: CR ChatGPT | E4: Claude | F4: CR Claude
A5: RN | B5: =COUNTIF('Mapeamento ChatGPT'!$E$2:$E$49,A5) -> 9 | C5: =COUNTIFS('Mapeamento ChatGPT'!$E$2:$E$49,A5,'Mapeamento ChatGPT'!$I$2:$I$49,"Identificada") -> 6 | D5: =IFERROR(C5/B5,"") -> 0.66666667 | E5: =COUNTIFS('Mapeamento Claude'!$E$2:$E$49,A5,'Mapeamento Claude'!$I$2:$I$49,"Identificada") -> 7 | F5: =IFERROR(E5/B5,"") -> 0.77777778
A6: RF | B6: =COUNTIF('Mapeamento ChatGPT'!$E$2:$E$49,A6) -> 27 | C6: =COUNTIFS('Mapeamento ChatGPT'!$E$2:$E$49,A6,'Mapeamento ChatGPT'!$I$2:$I$49,"Identificada") -> 21 | D6: =IFERROR(C6/B6,"") -> 0.77777778 | E6: =COUNTIFS('Mapeamento Claude'!$E$2:$E$49,A6,'Mapeamento Claude'!$I$2:$I$49,"Identificada") -> 25 | F6: =IFERROR(E6/B6,"") -> 0.92592593
A7: RNF | B7: =COUNTIF('Mapeamento ChatGPT'!$E$2:$E$49,A7) -> 5 | C7: =COUNTIFS('Mapeamento ChatGPT'!$E$2:$E$49,A7,'Mapeamento ChatGPT'!$I$2:$I$49,"Identificada") -> 4 | D7: =IFERROR(C7/B7,"") -> 0.8 | E7: =COUNTIFS('Mapeamento Claude'!$E$2:$E$49,A7,'Mapeamento Claude'!$I$2:$I$49,"Identificada") -> 5 | F7: =IFERROR(E7/B7,"") -> 1
A8: RST | B8: =COUNTIF('Mapeamento ChatGPT'!$E$2:$E$49,A8) -> 7 | C8: =COUNTIFS('Mapeamento ChatGPT'!$E$2:$E$49,A8,'Mapeamento ChatGPT'!$I$2:$I$49,"Identificada") -> 6 | D8: =IFERROR(C8/B8,"") -> 0.85714286 | E8: =COUNTIFS('Mapeamento Claude'!$E$2:$E$49,A8,'Mapeamento Claude'!$I$2:$I$49,"Identificada") -> 7 | F8: =IFERROR(E8/B8,"") -> 1
A9: TOTAL | B9: =SUM(B5:B8) -> 48 | C9: =SUM(C5:C8) -> 37 | D9: =IFERROR(C9/B9,"") -> 0.77083333 | E9: =SUM(E5:E8) -> 44 | F9: =IFERROR(E9/B9,"") -> 0.91666667
A12: 2. Adequação da classificação (entre os identificados)
A13: Situação | B13: ChatGPT | C13: Claude
A14: Coincide | B14: =COUNTIF('Mapeamento ChatGPT'!$J$2:$J$49,A14) -> 28 | C14: =COUNTIF('Mapeamento Claude'!$J$2:$J$49,A14) -> 35
A15: Diverge | B15: =COUNTIF('Mapeamento ChatGPT'!$J$2:$J$49,A15) -> 9 | C15: =COUNTIF('Mapeamento Claude'!$J$2:$J$49,A15) -> 9
A17: 3. Elementos gerados sem correspondência direta na especificação de referência
A18: Sustentação | B18: ChatGPT | C18: Claude
A19: Adicional sustentado | B19: =COUNTIFS('Requisitos Extras'!$B$3:$B$36,"ChatGPT",'Requisitos Extras'!$F$3:$F$36,A19) -> 11 | C19: =COUNTIFS('Requisitos Extras'!$B$3:$B$36,"Claude",'Requisitos Extras'!$F$3:$F$36,A19) -> 21
A20: Não | B20: =COUNTIFS('Requisitos Extras'!$B$3:$B$36,"ChatGPT",'Requisitos Extras'!$F$3:$F$36,A20) -> 1 | C20: =COUNTIFS('Requisitos Extras'!$B$3:$B$36,"Claude",'Requisitos Extras'!$F$3:$F$36,A20) -> 1
A22: TOTAL | B22: =SUM(B19:B20) -> 12 | C22: =SUM(C19:C20) -> 22
A26: 4. Critérios de qualidade (nº de elementos gerados: A = Atende, AP = Atende Parcialmente, NA = Não Atende)
A27: Critério | B27: ChatGPT: A | C27: ChatGPT: AP | D27: ChatGPT: NA | E27: Claude: A | F27: Claude: AP | G27: Claude: NA
A28: Corretude | B28: =COUNTIFS(Avaliação!$B$2:$B$109,"ChatGPT",Avaliação!$G$2:$G$109,"A") -> 47 | C28: =COUNTIFS(Avaliação!$B$2:$B$109,"ChatGPT",Avaliação!$G$2:$G$109,"AP") -> 2 | D28: =COUNTIFS(Avaliação!$B$2:$B$109,"ChatGPT",Avaliação!$G$2:$G$109,"NA") -> 0 | E28: =COUNTIFS(Avaliação!$B$2:$B$109,"Claude",Avaliação!$G$2:$G$109,"A") -> 58 | F28: =COUNTIFS(Avaliação!$B$2:$B$109,"Claude",Avaliação!$G$2:$G$109,"AP") -> 1 | G28: =COUNTIFS(Avaliação!$B$2:$B$109,"Claude",Avaliação!$G$2:$G$109,"NA") -> 0
A29: Completude | B29: =COUNTIFS(Avaliação!$B$2:$B$109,"ChatGPT",Avaliação!$H$2:$H$109,"A") -> 35 | C29: =COUNTIFS(Avaliação!$B$2:$B$109,"ChatGPT",Avaliação!$H$2:$H$109,"AP") -> 14 | D29: =COUNTIFS(Avaliação!$B$2:$B$109,"ChatGPT",Avaliação!$H$2:$H$109,"NA") -> 0 | E29: =COUNTIFS(Avaliação!$B$2:$B$109,"Claude",Avaliação!$H$2:$H$109,"A") -> 50 | F29: =COUNTIFS(Avaliação!$B$2:$B$109,"Claude",Avaliação!$H$2:$H$109,"AP") -> 9 | G29: =COUNTIFS(Avaliação!$B$2:$B$109,"Claude",Avaliação!$H$2:$H$109,"NA") -> 0
A30: Não ambiguidade | B30: =COUNTIFS(Avaliação!$B$2:$B$109,"ChatGPT",Avaliação!$I$2:$I$109,"A") -> 28 | C30: =COUNTIFS(Avaliação!$B$2:$B$109,"ChatGPT",Avaliação!$I$2:$I$109,"AP") -> 21 | D30: =COUNTIFS(Avaliação!$B$2:$B$109,"ChatGPT",Avaliação!$I$2:$I$109,"NA") -> 0 | E30: =COUNTIFS(Avaliação!$B$2:$B$109,"Claude",Avaliação!$I$2:$I$109,"A") -> 48 | F30: =COUNTIFS(Avaliação!$B$2:$B$109,"Claude",Avaliação!$I$2:$I$109,"AP") -> 11 | G30: =COUNTIFS(Avaliação!$B$2:$B$109,"Claude",Avaliação!$I$2:$I$109,"NA") -> 0
A31: Verificabilidade | B31: =COUNTIFS(Avaliação!$B$2:$B$109,"ChatGPT",Avaliação!$J$2:$J$109,"A") -> 34 | C31: =COUNTIFS(Avaliação!$B$2:$B$109,"ChatGPT",Avaliação!$J$2:$J$109,"AP") -> 15 | D31: =COUNTIFS(Avaliação!$B$2:$B$109,"ChatGPT",Avaliação!$J$2:$J$109,"NA") -> 0 | E31: =COUNTIFS(Avaliação!$B$2:$B$109,"Claude",Avaliação!$J$2:$J$109,"A") -> 49 | F31: =COUNTIFS(Avaliação!$B$2:$B$109,"Claude",Avaliação!$J$2:$J$109,"AP") -> 10 | G31: =COUNTIFS(Avaliação!$B$2:$B$109,"Claude",Avaliação!$J$2:$J$109,"NA") -> 0
A32: Total de avaliações | B32: =SUM(B28:B31) -> 144 | C32: =SUM(C28:C31) -> 52 | D32: =SUM(D28:D31) -> 0 | E32: =SUM(E28:E31) -> 205 | F32: =SUM(F28:F31) -> 31 | G32: =SUM(G28:G31) -> 0
A33: Atende ÷ total de avaliações | B33: =B32/SUM(B32:D32) -> 0.73469388 | E33: =E32/SUM(E32:G32) -> 0.86864407
A34: LLM | B34: Tipo | C34: Total avaliados | D34: Corretude A (%) | E34: Completude A (%) | F34: Não ambiguidade A (%) | G34: Verificabilidade A (%) | H34: Média A (%)
A35: ChatGPT | B35: RN | C35: =COUNTIFS(Avaliação!$B$2:$B$109,A35,Avaliação!$D$2:$D$109,B35) -> 16 | D35: =IF($C35=0,0,COUNTIFS(Avaliação!$B$2:$B$109,$A35,Avaliação!$D$2:$D$109,$B35,Avaliação!$G$2:$G$109,"A")/$C35) -> 1 | E35: =IF($C35=0,0,COUNTIFS(Avaliação!$B$2:$B$109,$A35,Avaliação!$D$2:$D$109,$B35,Avaliação!$H$2:$H$109,"A")/$C35) -> 0.9375 | F35: =IF($C35=0,0,COUNTIFS(Avaliação!$B$2:$B$109,$A35,Avaliação!$D$2:$D$109,$B35,Avaliação!$I$2:$I$109,"A")/$C35) -> 0.6875 | G35: =IF($C35=0,0,COUNTIFS(Avaliação!$B$2:$B$109,$A35,Avaliação!$D$2:$D$109,$B35,Avaliação!$J$2:$J$109,"A")/$C35) -> 0.875 | H35: =AVERAGE(D35:G35) -> 0.875
A36: ChatGPT | B36: RF | C36: =COUNTIFS(Avaliação!$B$2:$B$109,A36,Avaliação!$D$2:$D$109,B36) -> 25 | D36: =IF($C36=0,0,COUNTIFS(Avaliação!$B$2:$B$109,$A36,Avaliação!$D$2:$D$109,$B36,Avaliação!$G$2:$G$109,"A")/$C36) -> 0.92 | E36: =IF($C36=0,0,COUNTIFS(Avaliação!$B$2:$B$109,$A36,Avaliação!$D$2:$D$109,$B36,Avaliação!$H$2:$H$109,"A")/$C36) -> 0.72 | F36: =IF($C36=0,0,COUNTIFS(Avaliação!$B$2:$B$109,$A36,Avaliação!$D$2:$D$109,$B36,Avaliação!$I$2:$I$109,"A")/$C36) -> 0.64 | G36: =IF($C36=0,0,COUNTIFS(Avaliação!$B$2:$B$109,$A36,Avaliação!$D$2:$D$109,$B36,Avaliação!$J$2:$J$109,"A")/$C36) -> 0.76 | H36: =AVERAGE(D36:G36) -> 0.76
A37: ChatGPT | B37: RNF | C37: =COUNTIFS(Avaliação!$B$2:$B$109,A37,Avaliação!$D$2:$D$109,B37) -> 7 | D37: =IF($C37=0,0,COUNTIFS(Avaliação!$B$2:$B$109,$A37,Avaliação!$D$2:$D$109,$B37,Avaliação!$G$2:$G$109,"A")/$C37) -> 1 | E37: =IF($C37=0,0,COUNTIFS(Avaliação!$B$2:$B$109,$A37,Avaliação!$D$2:$D$109,$B37,Avaliação!$H$2:$H$109,"A")/$C37) -> 0.14285714 | F37: =IF($C37=0,0,COUNTIFS(Avaliação!$B$2:$B$109,$A37,Avaliação!$D$2:$D$109,$B37,Avaliação!$I$2:$I$109,"A")/$C37) -> 0.14285714 | G37: =IF($C37=0,0,COUNTIFS(Avaliação!$B$2:$B$109,$A37,Avaliação!$D$2:$D$109,$B37,Avaliação!$J$2:$J$109,"A")/$C37) -> 0 | H37: =AVERAGE(D37:G37) -> 0.32142857
A38: ChatGPT | B38: RST | C38: =COUNTIFS(Avaliação!$B$2:$B$109,A38,Avaliação!$D$2:$D$109,B38) -> 1 | D38: =IF($C38=0,0,COUNTIFS(Avaliação!$B$2:$B$109,$A38,Avaliação!$D$2:$D$109,$B38,Avaliação!$G$2:$G$109,"A")/$C38) -> 1 | E38: =IF($C38=0,0,COUNTIFS(Avaliação!$B$2:$B$109,$A38,Avaliação!$D$2:$D$109,$B38,Avaliação!$H$2:$H$109,"A")/$C38) -> 1 | F38: =IF($C38=0,0,COUNTIFS(Avaliação!$B$2:$B$109,$A38,Avaliação!$D$2:$D$109,$B38,Avaliação!$I$2:$I$109,"A")/$C38) -> 0 | G38: =IF($C38=0,0,COUNTIFS(Avaliação!$B$2:$B$109,$A38,Avaliação!$D$2:$D$109,$B38,Avaliação!$J$2:$J$109,"A")/$C38) -> 1 | H38: =AVERAGE(D38:G38) -> 0.75
A39: ChatGPT | B39: TOTAL | C39: =COUNTIF(Avaliação!$B$2:$B$109,A39) -> 49 | D39: =IF($C39=0,0,COUNTIFS(Avaliação!$B$2:$B$109,$A39,Avaliação!$G$2:$G$109,"A")/$C39) -> 0.95918367 | E39: =IF($C39=0,0,COUNTIFS(Avaliação!$B$2:$B$109,$A39,Avaliação!$H$2:$H$109,"A")/$C39) -> 0.71428571 | F39: =IF($C39=0,0,COUNTIFS(Avaliação!$B$2:$B$109,$A39,Avaliação!$I$2:$I$109,"A")/$C39) -> 0.57142857 | G39: =IF($C39=0,0,COUNTIFS(Avaliação!$B$2:$B$109,$A39,Avaliação!$J$2:$J$109,"A")/$C39) -> 0.69387755 | H39: =AVERAGE(D39:G39) -> 0.73469388
A40: Claude | B40: RN | C40: =COUNTIFS(Avaliação!$B$2:$B$109,A40,Avaliação!$D$2:$D$109,B40) -> 13 | D40: =IF($C40=0,0,COUNTIFS(Avaliação!$B$2:$B$109,$A40,Avaliação!$D$2:$D$109,$B40,Avaliação!$G$2:$G$109,"A")/$C40) -> 1 | E40: =IF($C40=0,0,COUNTIFS(Avaliação!$B$2:$B$109,$A40,Avaliação!$D$2:$D$109,$B40,Avaliação!$H$2:$H$109,"A")/$C40) -> 1 | F40: =IF($C40=0,0,COUNTIFS(Avaliação!$B$2:$B$109,$A40,Avaliação!$D$2:$D$109,$B40,Avaliação!$I$2:$I$109,"A")/$C40) -> 0.84615385 | G40: =IF($C40=0,0,COUNTIFS(Avaliação!$B$2:$B$109,$A40,Avaliação!$D$2:$D$109,$B40,Avaliação!$J$2:$J$109,"A")/$C40) -> 0.92307692 | H40: =AVERAGE(D40:G40) -> 0.94230769
A41: Claude | B41: RF | C41: =COUNTIFS(Avaliação!$B$2:$B$109,A41,Avaliação!$D$2:$D$109,B41) -> 24 | D41: =IF($C41=0,0,COUNTIFS(Avaliação!$B$2:$B$109,$A41,Avaliação!$D$2:$D$109,$B41,Avaliação!$G$2:$G$109,"A")/$C41) -> 0.95833333 | E41: =IF($C41=0,0,COUNTIFS(Avaliação!$B$2:$B$109,$A41,Avaliação!$D$2:$D$109,$B41,Avaliação!$H$2:$H$109,"A")/$C41) -> 1 | F41: =IF($C41=0,0,COUNTIFS(Avaliação!$B$2:$B$109,$A41,Avaliação!$D$2:$D$109,$B41,Avaliação!$I$2:$I$109,"A")/$C41) -> 0.83333333 | G41: =IF($C41=0,0,COUNTIFS(Avaliação!$B$2:$B$109,$A41,Avaliação!$D$2:$D$109,$B41,Avaliação!$J$2:$J$109,"A")/$C41) -> 0.95833333 | H41: =AVERAGE(D41:G41) -> 0.9375
A42: Claude | B42: RNF | C42: =COUNTIFS(Avaliação!$B$2:$B$109,A42,Avaliação!$D$2:$D$109,B42) -> 17 | D42: =IF($C42=0,0,COUNTIFS(Avaliação!$B$2:$B$109,$A42,Avaliação!$D$2:$D$109,$B42,Avaliação!$G$2:$G$109,"A")/$C42) -> 1 | E42: =IF($C42=0,0,COUNTIFS(Avaliação!$B$2:$B$109,$A42,Avaliação!$D$2:$D$109,$B42,Avaliação!$H$2:$H$109,"A")/$C42) -> 0.70588235 | F42: =IF($C42=0,0,COUNTIFS(Avaliação!$B$2:$B$109,$A42,Avaliação!$D$2:$D$109,$B42,Avaliação!$I$2:$I$109,"A")/$C42) -> 0.94117647 | G42: =IF($C42=0,0,COUNTIFS(Avaliação!$B$2:$B$109,$A42,Avaliação!$D$2:$D$109,$B42,Avaliação!$J$2:$J$109,"A")/$C42) -> 0.76470588 | H42: =AVERAGE(D42:G42) -> 0.85294118
A43: Claude | B43: RST | C43: =COUNTIFS(Avaliação!$B$2:$B$109,A43,Avaliação!$D$2:$D$109,B43) -> 5 | D43: =IF($C43=0,0,COUNTIFS(Avaliação!$B$2:$B$109,$A43,Avaliação!$D$2:$D$109,$B43,Avaliação!$G$2:$G$109,"A")/$C43) -> 1 | E43: =IF($C43=0,0,COUNTIFS(Avaliação!$B$2:$B$109,$A43,Avaliação!$D$2:$D$109,$B43,Avaliação!$H$2:$H$109,"A")/$C43) -> 0.2 | F43: =IF($C43=0,0,COUNTIFS(Avaliação!$B$2:$B$109,$A43,Avaliação!$D$2:$D$109,$B43,Avaliação!$I$2:$I$109,"A")/$C43) -> 0.2 | G43: =IF($C43=0,0,COUNTIFS(Avaliação!$B$2:$B$109,$A43,Avaliação!$D$2:$D$109,$B43,Avaliação!$J$2:$J$109,"A")/$C43) -> 0.2 | H43: =AVERAGE(D43:G43) -> 0.4
A44: Claude | B44: TOTAL | C44: =COUNTIF(Avaliação!$B$2:$B$109,A44) -> 59 | D44: =IF($C44=0,0,COUNTIFS(Avaliação!$B$2:$B$109,$A44,Avaliação!$G$2:$G$109,"A")/$C44) -> 0.98305085 | E44: =IF($C44=0,0,COUNTIFS(Avaliação!$B$2:$B$109,$A44,Avaliação!$H$2:$H$109,"A")/$C44) -> 0.84745763 | F44: =IF($C44=0,0,COUNTIFS(Avaliação!$B$2:$B$109,$A44,Avaliação!$I$2:$I$109,"A")/$C44) -> 0.81355932 | G44: =IF($C44=0,0,COUNTIFS(Avaliação!$B$2:$B$109,$A44,Avaliação!$J$2:$J$109,"A")/$C44) -> 0.83050847 | H44: =AVERAGE(D44:G44) -> 0.86864407
A45: Média A (%): média aritmética simples dos quatro percentuais de Atende. Nos totais, coincide com a razão Atende ÷ total de avaliações da linha 33 (total de avaliações = elementos × 4 critérios).
A47: 5. Volume de elementos gerados em relação à referência
A48: Indicador | B48: ChatGPT | C48: Claude
A49: Elementos gerados | B49: =COUNTIF(Avaliação!$B$2:$B$109,"ChatGPT") -> 49 | C49: =COUNTIF(Avaliação!$B$2:$B$109,"Claude") -> 59
...
